Not Found: /media/images/cars/avatar2.jpg
Not Found: /media/images/cars/avatar1.jpg
Not Found: /media/images/cars/avatar1.jpg
Not Found: /media/images/cars/avatar1_1.jpg
Not Found: /media/images/cars/54912.jpg
Not Found: /media/images/cars/54912_1.jpg
Not Found: /media/images/
Not Found: /
Not Found: /media/images/cars/54912_2.jpg
Internal Server Error: /admin/catalog/brand/
Traceback (most recent call last):
  File "C:\Program Files\Python27\lib\site-packages\django\core\handlers\base.py", line 112, in get_response
    response = wrapped_callback(request, *callback_args, **callback_kwargs)
  File "C:\Program Files\Python27\lib\site-packages\django\contrib\admin\options.py", line 432, in wrapper
    return self.admin_site.admin_view(view)(*args, **kwargs)
  File "C:\Program Files\Python27\lib\site-packages\django\utils\decorators.py", line 99, in _wrapped_view
    response = view_func(request, *args, **kwargs)
  File "C:\Program Files\Python27\lib\site-packages\django\views\decorators\cache.py", line 52, in _wrapped_view_func
    response = view_func(request, *args, **kwargs)
  File "C:\Program Files\Python27\lib\site-packages\django\contrib\admin\sites.py", line 198, in inner
    return view(request, *args, **kwargs)
  File "C:\Program Files\Python27\lib\site-packages\django\utils\decorators.py", line 29, in _wrapper
    return bound_func(*args, **kwargs)
  File "C:\Program Files\Python27\lib\site-packages\django\utils\decorators.py", line 99, in _wrapped_view
    response = view_func(request, *args, **kwargs)
  File "C:\Program Files\Python27\lib\site-packages\django\utils\decorators.py", line 25, in bound_func
    return func(self, *args2, **kwargs2)
  File "C:\Program Files\Python27\lib\site-packages\django\contrib\admin\options.py", line 1306, in changelist_view
    self)
  File "C:\Program Files\Python27\lib\site-packages\django\contrib\admin\views\main.py", line 106, in __init__
    self.get_results(request)
  File "C:\Program Files\Python27\lib\site-packages\django\contrib\admin\views\main.py", line 220, in get_results
    result_count = paginator.count
  File "C:\Program Files\Python27\lib\site-packages\django\core\paginator.py", line 72, in _get_count
    self._count = self.object_list.count()
  File "C:\Program Files\Python27\lib\site-packages\django\db\models\query.py", line 294, in count
    return self.query.get_count(using=self.db)
  File "C:\Program Files\Python27\lib\site-packages\django\db\models\sql\query.py", line 390, in get_count
    number = obj.get_aggregation(using=using)[None]
  File "C:\Program Files\Python27\lib\site-packages\django\db\models\sql\query.py", line 356, in get_aggregation
    result = query.get_compiler(using).execute_sql(SINGLE)
  File "C:\Program Files\Python27\lib\site-packages\django\db\models\sql\compiler.py", line 786, in execute_sql
    cursor.execute(sql, params)
  File "C:\Program Files\Python27\lib\site-packages\django\db\backends\util.py", line 69, in execute
    return super(CursorDebugWrapper, self).execute(sql, params)
  File "C:\Program Files\Python27\lib\site-packages\django\db\backends\util.py", line 53, in execute
    return self.cursor.execute(sql, params)
  File "C:\Program Files\Python27\lib\site-packages\django\db\utils.py", line 99, in __exit__
    six.reraise(dj_exc_type, dj_exc_value, traceback)
  File "C:\Program Files\Python27\lib\site-packages\django\db\backends\util.py", line 53, in execute
    return self.cursor.execute(sql, params)
  File "C:\Program Files\Python27\lib\site-packages\django\db\backends\mysql\base.py", line 124, in execute
    return self.cursor.execute(query, args)
  File "C:\Program Files\Python27\lib\site-packages\MySQLdb\cursors.py", line 202, in execute
    self.errorhandler(self, exc, value)
  File "C:\Program Files\Python27\lib\site-packages\MySQLdb\connections.py", line 36, in defaulterrorhandler
    raise errorclass, errorvalue
ProgrammingError: (1146, "Table 'rsoi_office_sys.catalog_brand' doesn't exist")
Internal Server Error: /admin/catalog/car/
Traceback (most recent call last):
  File "C:\Program Files\Python27\lib\site-packages\django\core\handlers\base.py", line 112, in get_response
    response = wrapped_callback(request, *callback_args, **callback_kwargs)
  File "C:\Program Files\Python27\lib\site-packages\django\contrib\admin\options.py", line 432, in wrapper
    return self.admin_site.admin_view(view)(*args, **kwargs)
  File "C:\Program Files\Python27\lib\site-packages\django\utils\decorators.py", line 99, in _wrapped_view
    response = view_func(request, *args, **kwargs)
  File "C:\Program Files\Python27\lib\site-packages\django\views\decorators\cache.py", line 52, in _wrapped_view_func
    response = view_func(request, *args, **kwargs)
  File "C:\Program Files\Python27\lib\site-packages\django\contrib\admin\sites.py", line 198, in inner
    return view(request, *args, **kwargs)
  File "C:\Program Files\Python27\lib\site-packages\django\utils\decorators.py", line 29, in _wrapper
    return bound_func(*args, **kwargs)
  File "C:\Program Files\Python27\lib\site-packages\django\utils\decorators.py", line 99, in _wrapped_view
    response = view_func(request, *args, **kwargs)
  File "C:\Program Files\Python27\lib\site-packages\django\utils\decorators.py", line 25, in bound_func
    return func(self, *args2, **kwargs2)
  File "C:\Program Files\Python27\lib\site-packages\django\contrib\admin\options.py", line 1411, in changelist_view
    'selection_note': _('0 of %(cnt)s selected') % {'cnt': len(cl.result_list)},
  File "C:\Program Files\Python27\lib\site-packages\django\db\models\query.py", line 77, in __len__
    self._fetch_all()
  File "C:\Program Files\Python27\lib\site-packages\django\db\models\query.py", line 857, in _fetch_all
    self._result_cache = list(self.iterator())
  File "C:\Program Files\Python27\lib\site-packages\django\db\models\query.py", line 220, in iterator
    for row in compiler.results_iter():
  File "C:\Program Files\Python27\lib\site-packages\django\db\models\sql\compiler.py", line 713, in results_iter
    for rows in self.execute_sql(MULTI):
  File "C:\Program Files\Python27\lib\site-packages\django\db\models\sql\compiler.py", line 786, in execute_sql
    cursor.execute(sql, params)
  File "C:\Program Files\Python27\lib\site-packages\django\db\backends\util.py", line 69, in execute
    return super(CursorDebugWrapper, self).execute(sql, params)
  File "C:\Program Files\Python27\lib\site-packages\django\db\backends\util.py", line 53, in execute
    return self.cursor.execute(sql, params)
  File "C:\Program Files\Python27\lib\site-packages\django\db\utils.py", line 99, in __exit__
    six.reraise(dj_exc_type, dj_exc_value, traceback)
  File "C:\Program Files\Python27\lib\site-packages\django\db\backends\util.py", line 53, in execute
    return self.cursor.execute(sql, params)
  File "C:\Program Files\Python27\lib\site-packages\django\db\backends\mysql\base.py", line 124, in execute
    return self.cursor.execute(query, args)
  File "C:\Program Files\Python27\lib\site-packages\MySQLdb\cursors.py", line 202, in execute
    self.errorhandler(self, exc, value)
  File "C:\Program Files\Python27\lib\site-packages\MySQLdb\connections.py", line 36, in defaulterrorhandler
    raise errorclass, errorvalue
OperationalError: (1054, "Unknown column 'catalog_car.brand_id' in 'field list'")
Internal Server Error: /admin/catalog/car/1/
Traceback (most recent call last):
  File "C:\Program Files\Python27\lib\site-packages\django\core\handlers\base.py", line 137, in get_response
    response = response.render()
  File "C:\Program Files\Python27\lib\site-packages\django\template\response.py", line 105, in render
    self.content = self.rendered_content
  File "C:\Program Files\Python27\lib\site-packages\django\template\response.py", line 82, in rendered_content
    content = template.render(context)
  File "C:\Program Files\Python27\lib\site-packages\django\template\base.py", line 140, in render
    return self._render(context)
  File "C:\Program Files\Python27\lib\site-packages\django\template\base.py", line 134, in _render
    return self.nodelist.render(context)
  File "C:\Program Files\Python27\lib\site-packages\django\template\base.py", line 840, in render
    bit = self.render_node(node, context)
  File "C:\Program Files\Python27\lib\site-packages\django\template\debug.py", line 78, in render_node
    return node.render(context)
  File "C:\Program Files\Python27\lib\site-packages\django\template\loader_tags.py", line 123, in render
    return compiled_parent._render(context)
  File "C:\Program Files\Python27\lib\site-packages\django\template\base.py", line 134, in _render
    return self.nodelist.render(context)
  File "C:\Program Files\Python27\lib\site-packages\django\template\base.py", line 840, in render
    bit = self.render_node(node, context)
  File "C:\Program Files\Python27\lib\site-packages\django\template\debug.py", line 78, in render_node
    return node.render(context)
  File "C:\Program Files\Python27\lib\site-packages\django\template\loader_tags.py", line 123, in render
    return compiled_parent._render(context)
  File "C:\Program Files\Python27\lib\site-packages\django\template\base.py", line 134, in _render
    return self.nodelist.render(context)
  File "C:\Program Files\Python27\lib\site-packages\django\template\base.py", line 840, in render
    bit = self.render_node(node, context)
  File "C:\Program Files\Python27\lib\site-packages\django\template\debug.py", line 78, in render_node
    return node.render(context)
  File "C:\Program Files\Python27\lib\site-packages\django\template\defaulttags.py", line 305, in render
    return nodelist.render(context)
  File "C:\Program Files\Python27\lib\site-packages\django\template\base.py", line 840, in render
    bit = self.render_node(node, context)
  File "C:\Program Files\Python27\lib\site-packages\django\template\debug.py", line 78, in render_node
    return node.render(context)
  File "C:\Program Files\Python27\lib\site-packages\django\template\loader_tags.py", line 62, in render
    result = block.nodelist.render(context)
  File "C:\Program Files\Python27\lib\site-packages\django\template\base.py", line 840, in render
    bit = self.render_node(node, context)
  File "C:\Program Files\Python27\lib\site-packages\django\template\debug.py", line 78, in render_node
    return node.render(context)
  File "C:\Program Files\Python27\lib\site-packages\django\template\defaulttags.py", line 305, in render
    return nodelist.render(context)
  File "C:\Program Files\Python27\lib\site-packages\django\template\base.py", line 840, in render
    bit = self.render_node(node, context)
  File "C:\Program Files\Python27\lib\site-packages\django\template\debug.py", line 78, in render_node
    return node.render(context)
  File "C:\Program Files\Python27\lib\site-packages\django\template\debug.py", line 88, in render
    output = self.filter_expression.resolve(context)
  File "C:\Program Files\Python27\lib\site-packages\django\template\base.py", line 613, in resolve
    new_obj = func(obj, *arg_vals)
  File "C:\Program Files\Python27\lib\site-packages\django\template\defaultfilters.py", line 40, in _dec
    args[0] = force_text(args[0])
  File "C:\Program Files\Python27\lib\site-packages\django\utils\encoding.py", line 100, in force_text
    s = s.__unicode__()
  File "D:\Dropbox\Семестр 10\РСОИ\rsoi\office_sys\catalog\models.py", line 48, in __unicode__
    return "%s %s" % (self.brand.name, self.model_name)
  File "C:\Program Files\Python27\lib\site-packages\django\db\models\fields\related.py", line 320, in __get__
    rel_obj = qs.get()
  File "C:\Program Files\Python27\lib\site-packages\django\db\models\query.py", line 310, in get
    self.model._meta.object_name)
DoesNotExist: Brand matching query does not exist.
Internal Server Error: /admin/catalog/
Traceback (most recent call last):
  File "C:\Program Files\Python27\lib\site-packages\django\core\handlers\base.py", line 99, in get_response
    resolver_match = resolver.resolve(request.path_info)
  File "C:\Program Files\Python27\lib\site-packages\django\core\urlresolvers.py", line 337, in resolve
    for pattern in self.url_patterns:
  File "C:\Program Files\Python27\lib\site-packages\django\core\urlresolvers.py", line 365, in url_patterns
    patterns = getattr(self.urlconf_module, "urlpatterns", self.urlconf_module)
  File "C:\Program Files\Python27\lib\site-packages\django\core\urlresolvers.py", line 360, in urlconf_module
    self._urlconf_module = import_module(self.urlconf_name)
  File "C:\Program Files\Python27\lib\site-packages\django\utils\importlib.py", line 40, in import_module
    __import__(name)
  File "D:\Dropbox\Семестр 10\РСОИ\rsoi\office_sys\office_sys\urls.py", line 4, in <module>
    admin.autodiscover()
  File "C:\Program Files\Python27\lib\site-packages\django\contrib\admin\__init__.py", line 29, in autodiscover
    import_module('%s.admin' % app)
  File "C:\Program Files\Python27\lib\site-packages\django\utils\importlib.py", line 40, in import_module
    __import__(name)
  File "D:\Dropbox\Семестр 10\РСОИ\rsoi\office_sys\catalog\admin.py", line 11, in <module>
    admin.site.register(Tariff)
  File "C:\Program Files\Python27\lib\site-packages\django\contrib\admin\sites.py", line 71, in register
    for model in model_or_iterable:
TypeError: 'classobj' object is not iterable
Internal Server Error: /admin/catalog/
Traceback (most recent call last):
  File "C:\Program Files\Python27\lib\site-packages\django\core\handlers\base.py", line 99, in get_response
    resolver_match = resolver.resolve(request.path_info)
  File "C:\Program Files\Python27\lib\site-packages\django\core\urlresolvers.py", line 337, in resolve
    for pattern in self.url_patterns:
  File "C:\Program Files\Python27\lib\site-packages\django\core\urlresolvers.py", line 365, in url_patterns
    patterns = getattr(self.urlconf_module, "urlpatterns", self.urlconf_module)
  File "C:\Program Files\Python27\lib\site-packages\django\core\urlresolvers.py", line 360, in urlconf_module
    self._urlconf_module = import_module(self.urlconf_name)
  File "C:\Program Files\Python27\lib\site-packages\django\utils\importlib.py", line 40, in import_module
    __import__(name)
  File "D:\Dropbox\Семестр 10\РСОИ\rsoi\office_sys\office_sys\urls.py", line 4, in <module>
    admin.autodiscover()
  File "C:\Program Files\Python27\lib\site-packages\django\contrib\admin\__init__.py", line 29, in autodiscover
    import_module('%s.admin' % app)
  File "C:\Program Files\Python27\lib\site-packages\django\utils\importlib.py", line 40, in import_module
    __import__(name)
  File "D:\Dropbox\Семестр 10\РСОИ\rsoi\office_sys\catalog\admin.py", line 11, in <module>
    admin.site.register(Tariff)
  File "C:\Program Files\Python27\lib\site-packages\django\contrib\admin\sites.py", line 71, in register
    for model in model_or_iterable:
TypeError: 'classobj' object is not iterable
Internal Server Error: /admin/catalog/
Traceback (most recent call last):
  File "C:\Program Files\Python27\lib\site-packages\django\core\handlers\base.py", line 99, in get_response
    resolver_match = resolver.resolve(request.path_info)
  File "C:\Program Files\Python27\lib\site-packages\django\core\urlresolvers.py", line 337, in resolve
    for pattern in self.url_patterns:
  File "C:\Program Files\Python27\lib\site-packages\django\core\urlresolvers.py", line 365, in url_patterns
    patterns = getattr(self.urlconf_module, "urlpatterns", self.urlconf_module)
  File "C:\Program Files\Python27\lib\site-packages\django\core\urlresolvers.py", line 360, in urlconf_module
    self._urlconf_module = import_module(self.urlconf_name)
  File "C:\Program Files\Python27\lib\site-packages\django\utils\importlib.py", line 40, in import_module
    __import__(name)
  File "D:\Dropbox\Семестр 10\РСОИ\rsoi\office_sys\office_sys\urls.py", line 4, in <module>
    admin.autodiscover()
  File "C:\Program Files\Python27\lib\site-packages\django\contrib\admin\__init__.py", line 29, in autodiscover
    import_module('%s.admin' % app)
  File "C:\Program Files\Python27\lib\site-packages\django\utils\importlib.py", line 40, in import_module
    __import__(name)
  File "D:\Dropbox\Семестр 10\РСОИ\rsoi\office_sys\catalog\admin.py", line 11, in <module>
    admin.site.register(Tariff)
  File "C:\Program Files\Python27\lib\site-packages\django\contrib\admin\sites.py", line 71, in register
    for model in model_or_iterable:
TypeError: 'classobj' object is not iterable
Internal Server Error: /admin/catalog/
Traceback (most recent call last):
  File "C:\Program Files\Python27\lib\site-packages\django\core\handlers\base.py", line 99, in get_response
    resolver_match = resolver.resolve(request.path_info)
  File "C:\Program Files\Python27\lib\site-packages\django\core\urlresolvers.py", line 337, in resolve
    for pattern in self.url_patterns:
  File "C:\Program Files\Python27\lib\site-packages\django\core\urlresolvers.py", line 365, in url_patterns
    patterns = getattr(self.urlconf_module, "urlpatterns", self.urlconf_module)
  File "C:\Program Files\Python27\lib\site-packages\django\core\urlresolvers.py", line 360, in urlconf_module
    self._urlconf_module = import_module(self.urlconf_name)
  File "C:\Program Files\Python27\lib\site-packages\django\utils\importlib.py", line 40, in import_module
    __import__(name)
  File "D:\Dropbox\Семестр 10\РСОИ\rsoi\office_sys\office_sys\urls.py", line 4, in <module>
    admin.autodiscover()
  File "C:\Program Files\Python27\lib\site-packages\django\contrib\admin\__init__.py", line 29, in autodiscover
    import_module('%s.admin' % app)
  File "C:\Program Files\Python27\lib\site-packages\django\utils\importlib.py", line 40, in import_module
    __import__(name)
  File "D:\Dropbox\Семестр 10\РСОИ\rsoi\office_sys\catalog\admin.py", line 11, in <module>
    admin.site.register(Tariff)
  File "C:\Program Files\Python27\lib\site-packages\django\contrib\admin\sites.py", line 71, in register
    for model in model_or_iterable:
TypeError: 'classobj' object is not iterable
Internal Server Error: /admin/catalog/
Traceback (most recent call last):
  File "C:\Program Files\Python27\lib\site-packages\django\core\handlers\base.py", line 99, in get_response
    resolver_match = resolver.resolve(request.path_info)
  File "C:\Program Files\Python27\lib\site-packages\django\core\urlresolvers.py", line 337, in resolve
    for pattern in self.url_patterns:
  File "C:\Program Files\Python27\lib\site-packages\django\core\urlresolvers.py", line 365, in url_patterns
    patterns = getattr(self.urlconf_module, "urlpatterns", self.urlconf_module)
  File "C:\Program Files\Python27\lib\site-packages\django\core\urlresolvers.py", line 360, in urlconf_module
    self._urlconf_module = import_module(self.urlconf_name)
  File "C:\Program Files\Python27\lib\site-packages\django\utils\importlib.py", line 40, in import_module
    __import__(name)
  File "D:\Dropbox\Семестр 10\РСОИ\rsoi\office_sys\office_sys\urls.py", line 4, in <module>
    admin.autodiscover()
  File "C:\Program Files\Python27\lib\site-packages\django\contrib\admin\__init__.py", line 29, in autodiscover
    import_module('%s.admin' % app)
  File "C:\Program Files\Python27\lib\site-packages\django\utils\importlib.py", line 40, in import_module
    __import__(name)
  File "D:\Dropbox\Семестр 10\РСОИ\rsoi\office_sys\catalog\admin.py", line 11, in <module>
    admin.site.register(Tariff)
  File "C:\Program Files\Python27\lib\site-packages\django\contrib\admin\sites.py", line 71, in register
    for model in model_or_iterable:
TypeError: 'classobj' object is not iterable
Internal Server Error: /admin/catalog/
Traceback (most recent call last):
  File "C:\Program Files\Python27\lib\site-packages\django\core\handlers\base.py", line 99, in get_response
    resolver_match = resolver.resolve(request.path_info)
  File "C:\Program Files\Python27\lib\site-packages\django\core\urlresolvers.py", line 337, in resolve
    for pattern in self.url_patterns:
  File "C:\Program Files\Python27\lib\site-packages\django\core\urlresolvers.py", line 365, in url_patterns
    patterns = getattr(self.urlconf_module, "urlpatterns", self.urlconf_module)
  File "C:\Program Files\Python27\lib\site-packages\django\core\urlresolvers.py", line 360, in urlconf_module
    self._urlconf_module = import_module(self.urlconf_name)
  File "C:\Program Files\Python27\lib\site-packages\django\utils\importlib.py", line 40, in import_module
    __import__(name)
  File "D:\Dropbox\Семестр 10\РСОИ\rsoi\office_sys\office_sys\urls.py", line 4, in <module>
    admin.autodiscover()
  File "C:\Program Files\Python27\lib\site-packages\django\contrib\admin\__init__.py", line 29, in autodiscover
    import_module('%s.admin' % app)
  File "C:\Program Files\Python27\lib\site-packages\django\utils\importlib.py", line 40, in import_module
    __import__(name)
  File "D:\Dropbox\Семестр 10\РСОИ\rsoi\office_sys\catalog\admin.py", line 11, in <module>
    admin.site.register(Tariff)
  File "C:\Program Files\Python27\lib\site-packages\django\contrib\admin\sites.py", line 71, in register
    for model in model_or_iterable:
TypeError: 'classobj' object is not iterable
Internal Server Error: /admin/catalog/
Traceback (most recent call last):
  File "C:\Program Files\Python27\lib\site-packages\django\core\handlers\base.py", line 99, in get_response
    resolver_match = resolver.resolve(request.path_info)
  File "C:\Program Files\Python27\lib\site-packages\django\core\urlresolvers.py", line 337, in resolve
    for pattern in self.url_patterns:
  File "C:\Program Files\Python27\lib\site-packages\django\core\urlresolvers.py", line 365, in url_patterns
    patterns = getattr(self.urlconf_module, "urlpatterns", self.urlconf_module)
  File "C:\Program Files\Python27\lib\site-packages\django\core\urlresolvers.py", line 360, in urlconf_module
    self._urlconf_module = import_module(self.urlconf_name)
  File "C:\Program Files\Python27\lib\site-packages\django\utils\importlib.py", line 40, in import_module
    __import__(name)
  File "D:\Dropbox\Семестр 10\РСОИ\rsoi\office_sys\office_sys\urls.py", line 4, in <module>
    admin.autodiscover()
  File "C:\Program Files\Python27\lib\site-packages\django\contrib\admin\__init__.py", line 29, in autodiscover
    import_module('%s.admin' % app)
  File "C:\Program Files\Python27\lib\site-packages\django\utils\importlib.py", line 40, in import_module
    __import__(name)
  File "D:\Dropbox\Семестр 10\РСОИ\rsoi\office_sys\catalog\admin.py", line 11, in <module>
    admin.site.register(Tariff)
  File "C:\Program Files\Python27\lib\site-packages\django\contrib\admin\sites.py", line 71, in register
    for model in model_or_iterable:
TypeError: 'classobj' object is not iterable
Internal Server Error: /admin/catalog/
Traceback (most recent call last):
  File "C:\Program Files\Python27\lib\site-packages\django\core\handlers\base.py", line 99, in get_response
    resolver_match = resolver.resolve(request.path_info)
  File "C:\Program Files\Python27\lib\site-packages\django\core\urlresolvers.py", line 337, in resolve
    for pattern in self.url_patterns:
  File "C:\Program Files\Python27\lib\site-packages\django\core\urlresolvers.py", line 365, in url_patterns
    patterns = getattr(self.urlconf_module, "urlpatterns", self.urlconf_module)
  File "C:\Program Files\Python27\lib\site-packages\django\core\urlresolvers.py", line 360, in urlconf_module
    self._urlconf_module = import_module(self.urlconf_name)
  File "C:\Program Files\Python27\lib\site-packages\django\utils\importlib.py", line 40, in import_module
    __import__(name)
  File "D:\Dropbox\Семестр 10\РСОИ\rsoi\office_sys\office_sys\urls.py", line 4, in <module>
    admin.autodiscover()
  File "C:\Program Files\Python27\lib\site-packages\django\contrib\admin\__init__.py", line 29, in autodiscover
    import_module('%s.admin' % app)
  File "C:\Program Files\Python27\lib\site-packages\django\utils\importlib.py", line 40, in import_module
    __import__(name)
  File "D:\Dropbox\Семестр 10\РСОИ\rsoi\office_sys\catalog\admin.py", line 11, in <module>
    admin.site.register(Tariff)
  File "C:\Program Files\Python27\lib\site-packages\django\contrib\admin\sites.py", line 71, in register
    for model in model_or_iterable:
TypeError: 'classobj' object is not iterable
Internal Server Error: /admin/catalog/
Traceback (most recent call last):
  File "C:\Program Files\Python27\lib\site-packages\django\core\handlers\base.py", line 99, in get_response
    resolver_match = resolver.resolve(request.path_info)
  File "C:\Program Files\Python27\lib\site-packages\django\core\urlresolvers.py", line 337, in resolve
    for pattern in self.url_patterns:
  File "C:\Program Files\Python27\lib\site-packages\django\core\urlresolvers.py", line 365, in url_patterns
    patterns = getattr(self.urlconf_module, "urlpatterns", self.urlconf_module)
  File "C:\Program Files\Python27\lib\site-packages\django\core\urlresolvers.py", line 360, in urlconf_module
    self._urlconf_module = import_module(self.urlconf_name)
  File "C:\Program Files\Python27\lib\site-packages\django\utils\importlib.py", line 40, in import_module
    __import__(name)
  File "D:\Dropbox\Семестр 10\РСОИ\rsoi\office_sys\office_sys\urls.py", line 4, in <module>
    admin.autodiscover()
  File "C:\Program Files\Python27\lib\site-packages\django\contrib\admin\__init__.py", line 29, in autodiscover
    import_module('%s.admin' % app)
  File "C:\Program Files\Python27\lib\site-packages\django\utils\importlib.py", line 40, in import_module
    __import__(name)
  File "D:\Dropbox\Семестр 10\РСОИ\rsoi\office_sys\catalog\admin.py", line 11, in <module>
    admin.site.register(Tariff)
  File "C:\Program Files\Python27\lib\site-packages\django\contrib\admin\sites.py", line 71, in register
    for model in model_or_iterable:
TypeError: 'classobj' object is not iterable
